Workbook
Name Bulan: [2]data!$B$2:$B$13
Name Tahun: [2]data!$C$2:$C$8

Sheet RAB PENDAPATAN
A1: ANGGARAN PENDAPATAN DAN BELANJA
A2: JEMAAT GMIM BUKIT MORIA TIKALA BARU
A3: TAHUN 2025
A5: I. PENDAPATAN
A6: Mata Anggaran | B6: URAIAN | C6: PENETAPAN ANGGARAN 2025 | D6: REALISASI ANGGARAN 2025 | E6: Persentasi
A9: 1.3.50.00 | B9: Persembahan Ibadah (Kotak dan Ekstra)
A10: 1.3.50.01 | B10: Persembahan Ibadah Subuh | C10: 150000000 | D10: =SUMIF([1]Transaksi!$C$6:$C$1048576,'RAB PENDAPATAN'!A10,[1]Transaksi!$F$6:$F$1048576) -> 114878500 | E10: =IF(OR(D10="",D10=0),"",D10/C10) -> 0.76585667
A11: 1.3.50.02 | B11: Persembahan Ibadah Pagi | C11: 225000000 | D11: =SUMIF([1]Transaksi!$C$6:$C$1048576,'RAB PENDAPATAN'!A11,[1]Transaksi!$F$6:$F$1048576) -> 148121000 | E11: =IF(OR(D11="",D11=0),"",D11/C11) -> 0.65831556
A12: 1.3.50.04 | B12: Persembahan Ibadah Malam | C12: 130000000 | D12: =SUMIF([1]Transaksi!$C$6:$C$1048576,'RAB PENDAPATAN'!A12,[1]Transaksi!$F$6:$F$1048576) -> 111814000 | E12: =IF(OR(D12="",D12=0),"",D12/C12) -> 0.86010769
B13: Jumlah Persembahan Ibadah | C13: =SUM(C10:C12) -> 505000000 | D13: =SUM(D10:D12) -> 374813500 | E13: =IF(OR(D13="",D13=0),"",D13/C13) -> 0.74220495
E14: =IF(OR(D14="",D14=0),"",D14/C14)
A15: 1.3.51.00 | B15: Persembahan Persepuluhan | C15: 50000000 | D15: =SUMIF([1]Transaksi!$C$6:$C$1048576,'RAB PENDAPATAN'!A15,[1]Transaksi!$F$6:$F$1048576) -> 25915000 | E15: =IF(OR(D15="",D15=0),"",D15/C15) -> 0.5183
B16: Jumlah Persembahan Persepuluhan | C16: =C15 -> 50000000 | D16: =D15 -> 25915000 | E16: =IF(OR(D16="",D16=0),"",D16/C16) -> 0.5183
E17: =IF(OR(D17="",D17=0),"",D17/C17)
A18: 1.3.01.00 | B18: Persembahan Ibd Kompelka BIPRA | E18: =IF(OR(D18="",D18=0),"",D18/C18)
A19: 1.3.01.01 | B19: Persembahan Ibadah Kompelka ARAS / Rayon Pria/Kaum Bapa | C19: 12500000 | D19: =SUMIF([1]Transaksi!$C$6:$C$1048576,'RAB PENDAPATAN'!A19,[1]Transaksi!$F$6:$F$1048576) -> 7704000 | E19: =IF(OR(D19="",D19=0),"",D19/C19) -> 0.61632
A20: 1.3.01.02 | B20: Persembahan Ibadah Kompelka ARAS / Rayon Wanita/Kaum Ibu | C20: 22500000 | D20: =SUMIF([1]Transaksi!$C$6:$C$1048576,'RAB PENDAPATAN'!A20,[1]Transaksi!$F$6:$F$1048576) -> 14546000 | E20: =IF(OR(D20="",D20=0),"",D20/C20) -> 0.64648889
A21: 1.3.01.03 | B21: Persembahan Ibadah Kompelka ARAS / Rayon Pemuda | C21: 10000000 | D21: =SUMIF([1]Transaksi!$C$6:$C$1048576,'RAB PENDAPATAN'!A21,[1]Transaksi!$F$6:$F$1048576) -> 785000 | E21: =IF(OR(D21="",D21=0),"",D21/C21) -> 0.0785
A22: 1.3.01.04 | B22: Persembahan Ibadah Kompelka ARAS / Rayon Remaja | C22: 2500000 | D22: =SUMIF([1]Transaksi!$C$6:$C$1048576,'RAB PENDAPATAN'!A22,[1]Transaksi!$F$6:$F$1048576) -> 1827000 | E22: =IF(OR(D22="",D22=0),"",D22/C22) -> 0.7308
A23: 1.3.01.05 | B23: Persembahan Ibadah Kompelka ARAS / Rayon Anak | C23: 5000000 | D23: =SUMIF([1]Transaksi!$C$6:$C$1048576,'RAB PENDAPATAN'!A23,[1]Transaksi!$F$6:$F$1048576) -> 144000 | E23: =IF(OR(D23="",D23=0),"",D23/C23) -> 0.0288
A24: 1.3.01.07 | B24: Persembahan Ibadah Kompelka ARAS / Rayon GSM | C24: 750000 | D24: =SUMIF([1]Transaksi!$C$6:$C$1048576,'RAB PENDAPATAN'!A24,[1]Transaksi!$F$6:$F$1048576) -> 0 | E24: =IF(OR(D24="",D24=0),"",D24/C24)
A25: 1.3.01.08 | B25: Persembahan Ibadah Kompelka ARAS / Rayon Lansia | C25: 14000000 | D25: =SUMIF([1]Transaksi!$C$6:$C$1048576,'RAB PENDAPATAN'!A25,[1]Transaksi!$F$6:$F$1048576) -> 8329000 | E25: =IF(OR(D25="",D25=0),"",D25/C25) -> 0.59492857
A26: 1.3.01.09 | B26: Pemuda Remaja Jemaat (Gabungan) | C26: 5000000 | D26: =SUMIF([1]Transaksi!$C$6:$C$1048576,'RAB PENDAPATAN'!A26,[1]Transaksi!$F$6:$F$1048576) -> 2470000 | E26: =IF(OR(D26="",D26=0),"",D26/C26) -> 0.494
B27: Total Persembahan Ibd Kompelka BIPRA | C27: =SUM(C19:C26) -> 72250000 | D27: =SUM(D19:D26) -> 35805000 | E27: =IF(OR(D27="",D27=0),"",D27/C27) -> 0.49557093
E28: =IF(OR(D28="",D28=0),"",D28/C28)
A29: 1.3.53.00 | B29: Persembahan Ibadah Kolom | E29: =IF(OR(D29="",D29=0),"",D29/C29)
A30: 1.3.53.01 | B30: Ibadah Perkunjungan Keluarga Rutin | C30: 160000000 | D30: =SUMIF([1]Transaksi!$C$6:$C$1048576,'RAB PENDAPATAN'!A30,[1]Transaksi!$F$6:$F$1048576) -> 105708500 | E30: =IF(OR(D30="",D30=0),"",D30/C30) -> 0.66067813
A31: 1.3.53.02 | B31: Persembahan Ibadah Kolom Pria/Kaum Bapa | C31: 35000000 | D31: =SUMIF([1]Transaksi!$C$6:$C$1048576,'RAB PENDAPATAN'!A31,[1]Transaksi!$F$6:$F$1048576) -> 24903000 | E31: =IF(OR(D31="",D31=0),"",D31/C31) -> 0.71151429
A32: 1.3.53.03 | B32: Persembahan Ibadah Kolom Wanita/Kaum Ibu | C32: 57500000 | D32: =SUMIF([1]Transaksi!$C$6:$C$1048576,'RAB PENDAPATAN'!A32,[1]Transaksi!$F$6:$F$1048576) -> 38625000 | E32: =IF(OR(D32="",D32=0),"",D32/C32) -> 0.67173913
A33: 1.3.53.04 | B33: Persembahan Ibadah Kolom Pemuda | C33: 1250000 | D33: =SUMIF([1]Transaksi!$C$6:$C$1048576,'RAB PENDAPATAN'!A33,[1]Transaksi!$F$6:$F$1048576) -> 0 | E33: =IF(OR(D33="",D33=0),"",D33/C33)
A34: 1.3.53.05 | B34: Persembahan Ibadah Kolom Remaja | C34: 500000 | D34: =SUMIF([1]Transaksi!$C$6:$C$1048576,'RAB PENDAPATAN'!A34,[1]Transaksi!$F$6:$F$1048576) -> 0 | E34: =IF(OR(D34="",D34=0),"",D34/C34)
A35: 1.3.53.06 | B35: Persembahan Ibadah Kolom ASM | C35: 10000000 | D35: =SUMIF([1]Transaksi!$C$6:$C$1048576,'RAB PENDAPATAN'!A35,[1]Transaksi!$F$6:$F$1048576) -> 5094000 | E35: =IF(OR(D35="",D35=0),"",D35/C35) -> 0.5094
A36: 1.3.53.07 | B36: Persembahan Ibadah Kolom - Syukur HUT Kelahiran/Organisasi | C36: 17500000 | D36: =SUMIF([1]Transaksi!$C$6:$C$1048576,'RAB PENDAPATAN'!A36,[1]Transaksi!$F$6:$F$1048576) -> 8754000 | E36: =IF(OR(D36="",D36=0),"",D36/C36) -> 0.50022857
A37: 1.3.53.08 | B37: Persembahan Ibadah Kolom - Syukur HUT Pernikahan | C37: 5000000 | D37: =SUMIF([1]Transaksi!$C$6:$C$1048576,'RAB PENDAPATAN'!A37,[1]Transaksi!$F$6:$F$1048576) -> 1689000 | E37: =IF(OR(D37="",D37=0),"",D37/C37) -> 0.3378
A38: 1.3.53.09 | B38: Persembahan Ibadah Kolom - Syukur Keluarga Lainnya | C38: 22500000 | D38: =SUMIF([1]Transaksi!$C$6:$C$1048576,'RAB PENDAPATAN'!A38,[1]Transaksi!$F$6:$F$1048576) -> 9763400 | E38: =IF(OR(D38="",D38=0),"",D38/C38) -> 0.43392889
A39: 1.3.53.10 | B39: Persembahan Ibadah Awal Bulan | C39: 3000000 | D39: =SUMIF([1]Transaksi!$C$6:$C$1048576,'RAB PENDAPATAN'!A39,[1]Transaksi!$F$6:$F$1048576) -> 423000 | E39: =IF(OR(D39="",D39=0),"",D39/C39) -> 0.141
A40: 1.3.53.11 | B40: Pemuda & Remaja Kolom (Gabungan) | C40: 500000 | D40: =SUMIF([1]Transaksi!$C$6:$C$1048576,'RAB PENDAPATAN'!A40,[1]Transaksi!$F$6:$F$1048576) -> 519000 | E40: =IF(OR(D40="",D40=0),"",D40/C40) -> 1.038
B41: Jumlah Persembahan Ibadah Kolom | C41: =SUM(C30:C40) -> 312750000 | D41: =SUM(D30:D40) -> 195478900 | E41: =IF(OR(D41="",D41=0),"",D41/C41) -> 0.62503245
E42: =IF(OR(D42="",D42=0),"",D42/C42)
A43: 1.3.54.00 | B43: PERSEMBAHAN IBADAH HARI RAYA | E43: =IF(OR(D43="",D43=0),"",D43/C43)
...
